{
 "cells": [
  {
   "cell_type": "code",
   "execution_count": 1,
   "metadata": {},
   "outputs": [
    {
     "name": "stderr",
     "output_type": "stream",
     "text": [
      "2023-05-31 15:46:56.559100: I tensorflow/core/platform/cpu_feature_guard.cc:182] This TensorFlow binary is optimized to use available CPU instructions in performance-critical operations.\n",
      "To enable the following instructions: AVX2 FMA, in other operations, rebuild TensorFlow with the appropriate compiler flags.\n",
      "2023-05-31 15:46:57.750116: W tensorflow/compiler/tf2tensorrt/utils/py_utils.cc:38] TF-TRT Warning: Could not find TensorRT\n",
      "/home/ezraf/miniconda3/envs/tf/lib/python3.11/site-packages/tqdm/auto.py:21: TqdmWarning: IProgress not found. Please update jupyter and ipywidgets. See https://ipywidgets.readthedocs.io/en/stable/user_install.html\n",
      "  from .autonotebook import tqdm as notebook_tqdm\n"
     ]
    }
   ],
   "source": [
    "import tensorflow as tf\n",
    "import tensorflow_datasets as tfds"
   ]
  },
  {
   "cell_type": "code",
   "execution_count": 2,
   "metadata": {},
   "outputs": [
    {
     "name": "stderr",
     "output_type": "stream",
     "text": [
      "2023-05-31 15:47:05.387048: I tensorflow/compiler/xla/stream_executor/cuda/cuda_gpu_executor.cc:982] could not open file to read NUMA node: /sys/bus/pci/devices/0000:01:00.0/numa_node\n",
      "Your kernel may have been built without NUMA support.\n",
      "2023-05-31 15:47:05.455919: I tensorflow/compiler/xla/stream_executor/cuda/cuda_gpu_executor.cc:982] could not open file to read NUMA node: /sys/bus/pci/devices/0000:01:00.0/numa_node\n",
      "Your kernel may have been built without NUMA support.\n",
      "2023-05-31 15:47:05.456018: I tensorflow/compiler/xla/stream_executor/cuda/cuda_gpu_executor.cc:982] could not open file to read NUMA node: /sys/bus/pci/devices/0000:01:00.0/numa_node\n",
      "Your kernel may have been built without NUMA support.\n",
      "2023-05-31 15:47:05.460445: I tensorflow/compiler/xla/stream_executor/cuda/cuda_gpu_executor.cc:982] could not open file to read NUMA node: /sys/bus/pci/devices/0000:01:00.0/numa_node\n",
      "Your kernel may have been built without NUMA support.\n",
      "2023-05-31 15:47:05.460584: I tensorflow/compiler/xla/stream_executor/cuda/cuda_gpu_executor.cc:982] could not open file to read NUMA node: /sys/bus/pci/devices/0000:01:00.0/numa_node\n",
      "Your kernel may have been built without NUMA support.\n",
      "2023-05-31 15:47:05.460663: I tensorflow/compiler/xla/stream_executor/cuda/cuda_gpu_executor.cc:982] could not open file to read NUMA node: /sys/bus/pci/devices/0000:01:00.0/numa_node\n",
      "Your kernel may have been built without NUMA support.\n",
      "2023-05-31 15:47:06.661541: I tensorflow/compiler/xla/stream_executor/cuda/cuda_gpu_executor.cc:982] could not open file to read NUMA node: /sys/bus/pci/devices/0000:01:00.0/numa_node\n",
      "Your kernel may have been built without NUMA support.\n",
      "2023-05-31 15:47:06.661814: I tensorflow/compiler/xla/stream_executor/cuda/cuda_gpu_executor.cc:982] could not open file to read NUMA node: /sys/bus/pci/devices/0000:01:00.0/numa_node\n",
      "Your kernel may have been built without NUMA support.\n",
      "2023-05-31 15:47:06.661827: I tensorflow/core/common_runtime/gpu/gpu_device.cc:1722] Could not identify NUMA node of platform GPU id 0, defaulting to 0.  Your kernel may not have been built with NUMA support.\n",
      "2023-05-31 15:47:06.661892: I tensorflow/compiler/xla/stream_executor/cuda/cuda_gpu_executor.cc:982] could not open file to read NUMA node: /sys/bus/pci/devices/0000:01:00.0/numa_node\n",
      "Your kernel may have been built without NUMA support.\n",
      "2023-05-31 15:47:06.661984: I tensorflow/core/common_runtime/gpu/gpu_device.cc:1635] Created device /job:localhost/replica:0/task:0/device:GPU:0 with 5379 MB memory:  -> device: 0, name: NVIDIA GeForce RTX 3070 Laptop GPU, pci bus id: 0000:01:00.0, compute capability: 8.6\n"
     ]
    }
   ],
   "source": [
    "(ds_train, ds_test), ds_info = tfds.load(\n",
    "    'mnist',\n",
    "    split=['train', 'test'],\n",
    "    shuffle_files=True,\n",
    "    as_supervised=True,\n",
    "    with_info=True,\n",
    ")"
   ]
  },
  {
   "cell_type": "code",
   "execution_count": 3,
   "metadata": {},
   "outputs": [],
   "source": [
    "def normalize_img(image, label):\n",
    "  \"\"\"Normalizes images: `uint8` -> `float32`.\"\"\"\n",
    "  return tf.cast(image, tf.float32) / 255., tf.one_hot(label, 10)\n",
    "\n",
    "ds_train = ds_train.map(\n",
    "    normalize_img, num_parallel_calls=tf.data.AUTOTUNE)\n",
    "ds_train = ds_train.cache()\n",
    "ds_train = ds_train.shuffle(ds_info.splits['train'].num_examples)\n",
    "ds_train = ds_train.batch(128)\n",
    "ds_train = ds_train.prefetch(tf.data.AUTOTUNE)"
   ]
  },
  {
   "cell_type": "code",
   "execution_count": 4,
   "metadata": {},
   "outputs": [],
   "source": [
    "ds_test = ds_test.map(\n",
    "    normalize_img, num_parallel_calls=tf.data.AUTOTUNE)\n",
    "ds_test = ds_test.batch(128)\n",
    "ds_test = ds_test.cache()\n",
    "ds_test = ds_test.prefetch(tf.data.AUTOTUNE)"
   ]
  },
  {
   "cell_type": "code",
   "execution_count": 27,
   "metadata": {},
   "outputs": [],
   "source": [
    "resnet = tf.keras.applications.resnet50.ResNet50(\n",
    "    include_top=True,\n",
    "    weights=None,\n",
    "    input_tensor=None,\n",
    "    input_shape=(32,32,1),\n",
    "    pooling=None,\n",
    "    classes=10,\n",
    ")"
   ]
  },
  {
   "cell_type": "code",
   "execution_count": 30,
   "metadata": {},
   "outputs": [],
   "source": [
    "cfg = resnet.get_config()\n",
    "cfg['layers'][0]['config']['batch_input_shape'] = (None, 28, 28, 1)\n",
    "model = tf.keras.Model.from_config(cfg)"
   ]
  },
  {
   "cell_type": "code",
   "execution_count": 32,
   "metadata": {},
   "outputs": [],
   "source": [
    "model.compile(\n",
    "    optimizer=tf.keras.optimizers.SGD(learning_rate=0.001, momentum=0.9),\n",
    "    loss=tf.keras.losses.CategoricalCrossentropy(from_logits=True),\n",
    "    metrics=[tf.keras.metrics.CategoricalAccuracy()],\n",
    ")"
   ]
  },
  {
   "cell_type": "code",
   "execution_count": 33,
   "metadata": {},
   "outputs": [
    {
     "name": "stdout",
     "output_type": "stream",
     "text": [
      "Epoch 1/6\n"
     ]
    },
    {
     "name": "stderr",
     "output_type": "stream",
     "text": [
      "2023-05-31 16:06:27.310304: I tensorflow/core/common_runtime/executor.cc:1197] [/device:CPU:0] (DEBUG INFO) Executor start aborting (this does not indicate an error and you can ignore this message): INVALID_ARGUMENT: You must feed a value for placeholder tensor 'Placeholder/_4' with dtype int64 and shape [1]\n",
      "\t [[{{node Placeholder/_4}}]]\n",
      "2023-05-31 16:06:27.311070: I tensorflow/core/common_runtime/executor.cc:1197] [/device:CPU:0] (DEBUG INFO) Executor start aborting (this does not indicate an error and you can ignore this message): INVALID_ARGUMENT: You must feed a value for placeholder tensor 'Placeholder/_2' with dtype string and shape [1]\n",
      "\t [[{{node Placeholder/_2}}]]\n"
     ]
    },
    {
     "ename": "ValueError",
     "evalue": "in user code:\n\n    File \"/home/ezraf/miniconda3/envs/tf/lib/python3.11/site-packages/keras/engine/training.py\", line 1284, in train_function  *\n        return step_function(self, iterator)\n    File \"/home/ezraf/miniconda3/envs/tf/lib/python3.11/site-packages/keras/engine/training.py\", line 1268, in step_function  **\n        outputs = model.distribute_strategy.run(run_step, args=(data,))\n    File \"/home/ezraf/miniconda3/envs/tf/lib/python3.11/site-packages/keras/engine/training.py\", line 1249, in run_step  **\n        outputs = model.train_step(data)\n    File \"/home/ezraf/miniconda3/envs/tf/lib/python3.11/site-packages/keras/engine/training.py\", line 1051, in train_step\n        loss = self.compute_loss(x, y, y_pred, sample_weight)\n    File \"/home/ezraf/miniconda3/envs/tf/lib/python3.11/site-packages/keras/engine/training.py\", line 1109, in compute_loss\n        return self.compiled_loss(\n    File \"/home/ezraf/miniconda3/envs/tf/lib/python3.11/site-packages/keras/engine/compile_utils.py\", line 265, in __call__\n        loss_value = loss_obj(y_t, y_p, sample_weight=sw)\n    File \"/home/ezraf/miniconda3/envs/tf/lib/python3.11/site-packages/keras/losses.py\", line 142, in __call__\n        losses = call_fn(y_true, y_pred)\n    File \"/home/ezraf/miniconda3/envs/tf/lib/python3.11/site-packages/keras/losses.py\", line 268, in call  **\n        return ag_fn(y_true, y_pred, **self._fn_kwargs)\n    File \"/home/ezraf/miniconda3/envs/tf/lib/python3.11/site-packages/keras/losses.py\", line 1984, in categorical_crossentropy\n        return backend.categorical_crossentropy(\n    File \"/home/ezraf/miniconda3/envs/tf/lib/python3.11/site-packages/keras/backend.py\", line 5559, in categorical_crossentropy\n        target.shape.assert_is_compatible_with(output.shape)\n\n    ValueError: Shapes (None, 1) and (None, 10) are incompatible\n",
     "output_type": "error",
     "traceback": [
      "\u001b[0;31m---------------------------------------------------------------------------\u001b[0m",
      "\u001b[0;31mValueError\u001b[0m                                Traceback (most recent call last)",
      "Cell \u001b[0;32mIn[33], line 1\u001b[0m\n\u001b[0;32m----> 1\u001b[0m model\u001b[39m.\u001b[39;49mfit(\n\u001b[1;32m      2\u001b[0m     ds_train,\n\u001b[1;32m      3\u001b[0m     epochs\u001b[39m=\u001b[39;49m\u001b[39m6\u001b[39;49m,\n\u001b[1;32m      4\u001b[0m     validation_data\u001b[39m=\u001b[39;49mds_test,\n\u001b[1;32m      5\u001b[0m )\n",
      "File \u001b[0;32m~/miniconda3/envs/tf/lib/python3.11/site-packages/keras/utils/traceback_utils.py:70\u001b[0m, in \u001b[0;36mfilter_traceback.<locals>.error_handler\u001b[0;34m(*args, **kwargs)\u001b[0m\n\u001b[1;32m     67\u001b[0m     filtered_tb \u001b[39m=\u001b[39m _process_traceback_frames(e\u001b[39m.\u001b[39m__traceback__)\n\u001b[1;32m     68\u001b[0m     \u001b[39m# To get the full stack trace, call:\u001b[39;00m\n\u001b[1;32m     69\u001b[0m     \u001b[39m# `tf.debugging.disable_traceback_filtering()`\u001b[39;00m\n\u001b[0;32m---> 70\u001b[0m     \u001b[39mraise\u001b[39;00m e\u001b[39m.\u001b[39mwith_traceback(filtered_tb) \u001b[39mfrom\u001b[39;00m \u001b[39mNone\u001b[39;00m\n\u001b[1;32m     71\u001b[0m \u001b[39mfinally\u001b[39;00m:\n\u001b[1;32m     72\u001b[0m     \u001b[39mdel\u001b[39;00m filtered_tb\n",
      "File \u001b[0;32m/tmp/__autograph_generated_fileu40dssuj.py:15\u001b[0m, in \u001b[0;36mouter_factory.<locals>.inner_factory.<locals>.tf__train_function\u001b[0;34m(iterator)\u001b[0m\n\u001b[1;32m     13\u001b[0m \u001b[39mtry\u001b[39;00m:\n\u001b[1;32m     14\u001b[0m     do_return \u001b[39m=\u001b[39m \u001b[39mTrue\u001b[39;00m\n\u001b[0;32m---> 15\u001b[0m     retval_ \u001b[39m=\u001b[39m ag__\u001b[39m.\u001b[39mconverted_call(ag__\u001b[39m.\u001b[39mld(step_function), (ag__\u001b[39m.\u001b[39mld(\u001b[39mself\u001b[39m), ag__\u001b[39m.\u001b[39mld(iterator)), \u001b[39mNone\u001b[39;00m, fscope)\n\u001b[1;32m     16\u001b[0m \u001b[39mexcept\u001b[39;00m:\n\u001b[1;32m     17\u001b[0m     do_return \u001b[39m=\u001b[39m \u001b[39mFalse\u001b[39;00m\n",
      "\u001b[0;31mValueError\u001b[0m: in user code:\n\n    File \"/home/ezraf/miniconda3/envs/tf/lib/python3.11/site-packages/keras/engine/training.py\", line 1284, in train_function  *\n        return step_function(self, iterator)\n    File \"/home/ezraf/miniconda3/envs/tf/lib/python3.11/site-packages/keras/engine/training.py\", line 1268, in step_function  **\n        outputs = model.distribute_strategy.run(run_step, args=(data,))\n    File \"/home/ezraf/miniconda3/envs/tf/lib/python3.11/site-packages/keras/engine/training.py\", line 1249, in run_step  **\n        outputs = model.train_step(data)\n    File \"/home/ezraf/miniconda3/envs/tf/lib/python3.11/site-packages/keras/engine/training.py\", line 1051, in train_step\n        loss = self.compute_loss(x, y, y_pred, sample_weight)\n    File \"/home/ezraf/miniconda3/envs/tf/lib/python3.11/site-packages/keras/engine/training.py\", line 1109, in compute_loss\n        return self.compiled_loss(\n    File \"/home/ezraf/miniconda3/envs/tf/lib/python3.11/site-packages/keras/engine/compile_utils.py\", line 265, in __call__\n        loss_value = loss_obj(y_t, y_p, sample_weight=sw)\n    File \"/home/ezraf/miniconda3/envs/tf/lib/python3.11/site-packages/keras/losses.py\", line 142, in __call__\n        losses = call_fn(y_true, y_pred)\n    File \"/home/ezraf/miniconda3/envs/tf/lib/python3.11/site-packages/keras/losses.py\", line 268, in call  **\n        return ag_fn(y_true, y_pred, **self._fn_kwargs)\n    File \"/home/ezraf/miniconda3/envs/tf/lib/python3.11/site-packages/keras/losses.py\", line 1984, in categorical_crossentropy\n        return backend.categorical_crossentropy(\n    File \"/home/ezraf/miniconda3/envs/tf/lib/python3.11/site-packages/keras/backend.py\", line 5559, in categorical_crossentropy\n        target.shape.assert_is_compatible_with(output.shape)\n\n    ValueError: Shapes (None, 1) and (None, 10) are incompatible\n"
     ]
    }
   ],
   "source": [
    "model.fit(\n",
    "    ds_train,\n",
    "    epochs=6,\n",
    "    validation_data=ds_test,\n",
    ")"
   ]
  },
  {
   "cell_type": "code",
   "execution_count": null,
   "metadata": {},
   "outputs": [],
   "source": []
  }
 ],
 "metadata": {
  "kernelspec": {
   "display_name": "tf",
   "language": "python",
   "name": "python3"
  },
  "language_info": {
   "codemirror_mode": {
    "name": "ipython",
    "version": 3
   },
   "file_extension": ".py",
   "mimetype": "text/x-python",
   "name": "python",
   "nbconvert_exporter": "python",
   "pygments_lexer": "ipython3",
   "version": "3.11.3"
  },
  "orig_nbformat": 4
 },
 "nbformat": 4,
 "nbformat_minor": 2
}
